<mujoco model="custom">
	<compiler angle="degree" inertiafromgeom="true"/>
	<default>
		<joint armature="1" damping="1" limited="true"/>
		<geom conaffinity="1" condim="3" friction="0.8 0.1 0.1" contype="1" margin="0.001" material="geom" rgba="0.8 0.6 .4 1"/>
		<motor ctrllimited="true" ctrlrange="-.4 .4"/>
	</default>
	<option integrator="RK4" iterations="50" solver="PGS" timestep="0.003">
		<!-- <flags solverstat="enable" energy="enable"/>-->
	</option>
	<size nkey="5" nuser_geom="1"/>
	<visual>
		<map fogend="5" fogstart="3"/>
	</visual>
	<worldbody>
		<!-- Butt is stuck in space -->
		<geom fromto="-.02 -.07 0 -.02 .07 0" name="butt" size="0.09" type="capsule" rgba="0.1 0.1 0.9 0.5"/>
		<!-- <geom fromto="0 &#45;.07 0 0 .07 0" name="torso1" size="0.07" type="capsule"/> -->
		<body name="pelvis" pos="0 0 0.06" quat="1.000 0 -0.002 0">
			<joint armature="0.02" axis="1 0 0" damping="5" name="abdomen_x" pos="0 0 0.01" range="-35 35" stiffness="10" type="hinge"/>
			<geom fromto="0 -.07 0 0 .07 0" name="midtorso1" size="0.07" type="capsule" rgba="0.1 0.9 0.1 0.5"/>
			<joint armature="0.02" axis="0 0 1" damping="5" name="abdomen_z" pos="0 0 0.065" range="-35 35" stiffness="20" type="hinge"/>
			<joint armature="0.02" axis="0 1 0" damping="5" name="abdomen_y" pos="0 0 0.065" range="-35 70" stiffness="10" type="hinge"/>

			<!-- <geom fromto="&#45;.02 &#45;.07 0 &#45;.02 .07 0" name="butt" size="0.09" type="capsule" rgba="0.1 0.1 0.9 0.5"/> -->
			<body name="torso" pos="0 0 0.13" quat="1.000 0 -0.002 0">
				<joint armature="0.02" axis="1 0 0" damping="5" name="abdomen_x" pos="0 0 0.01" range="-35 35" stiffness="10" type="hinge"/>
				<geom fromto="0 -.06 0 0 .06 0" name="lwaist" size="0.09" type="capsule" rgba="0.9 0.1 0.1 0.5"/>

				<!-- Right arm -->
				<body name="right_upper_arm" pos="0 -0.17 0.06">
					<joint armature="0.0068" axis="2 1 1" name="right_shoulder1" pos="0 0 0" range="-85 60" stiffness="1" type="hinge"/>
					<joint armature="0.0051" axis="0 -1 1" name="right_shoulder2" pos="0 0 0" range="-85 60" stiffness="1" type="hinge"/>
					<geom fromto="0 0 0 .16 -.16 -.16" name="right_uarm1" size="0.04 0.16" type="capsule"/>
					<body name="right_lower_arm" pos=".18 -.18 -.18">
						<joint armature="0.0028" axis="0 -1 1" name="right_elbow" pos="0 0 0" range="-90 50" stiffness="0" type="hinge"/>
						<geom fromto="0.01 0.01 0.01 .17 .17 .17" name="right_larm" size="0.031" type="capsule"/>
						<geom name="right_hand" pos=".18 .18 .18" size="0.04" type="sphere"/>
					</body>
				</body>

				<!-- Left arm -->
				<body name="left_upper_arm" pos="0 0.17 0.06">
					<joint armature="0.0068" axis="2 -1 1" name="left_shoulder1" pos="0 0 0" range="-60 85" stiffness="1" type="hinge"/>
					<joint armature="0.0051" axis="0 1 1" name="left_shoulder2" pos="0 0 0" range="-60 85" stiffness="1" type="hinge"/>
					<geom fromto="0 0 0 .16 .16 -.16" name="left_uarm1" size="0.04 0.16" type="capsule"/>
					<body name="left_lower_arm" pos=".18 .18 -.18">
						<joint armature="0.0028" axis="0 -1 -1" name="left_elbow" pos="0 0 0" range="-90 50" stiffness="0" type="hinge"/>
						<geom fromto="0.01 -0.01 0.01 .17 -.17 .17" name="left_larm" size="0.031" type="capsule"/>
						<geom name="left_hand" pos=".18 -.18 .18" size="0.04" type="sphere"/>
					</body>
				</body>
				<!-- Head and Neck -->
				<body name="head" pos="0 0 0.15" quat="1.000 0 -0.002 0">
					<joint armature="0.02" axis="1 0 0" damping="5" name="neck_x" pos="0 0 0.05" range="-35 35" stiffness="10" type="hinge"/>
					<joint armature="0.02" axis="0 1 0" damping="5" name="neck_y" pos="0 0 0.05" range="-35 35" stiffness="10" type="hinge"/>
					<joint armature="0.02" axis="0 0 1" damping="5" name="neck_z" pos="0 0 0.05" range="-35 35" stiffness="10" type="hinge"/>
					<geom name="head" pos="0 0 .05" size=".09" type="sphere" user="258"/>
				</body>
			</body>
		</body>
	</worldbody>
	<actuator><!-- this section is not supported, same constants in code -->
		<motor gear="100" joint="abdomen_y" name="abdomen_y"/>
		<motor gear="100" joint="abdomen_z" name="abdomen_z"/>
		<motor gear="100" joint="abdomen_x" name="abdomen_x"/>
		<motor gear="25" joint="right_shoulder1" name="right_shoulder1"/>
		<motor gear="25" joint="right_shoulder2" name="right_shoulder2"/>
		<motor gear="25" joint="right_elbow" name="right_elbow"/>
		<motor gear="25" joint="left_shoulder1" name="left_shoulder1"/>
		<motor gear="25" joint="left_shoulder2" name="left_shoulder2"/>
		<motor gear="25" joint="left_elbow" name="left_elbow"/>
	</actuator>
</mujoco>
