<mujoco model="Social Torso">
	<compiler angle="degree" inertiafromgeom="true"/>

	<default>
		<joint armature="1" damping="1" limited="true"/>
		<geom conaffinity="1" condim="3" friction="0.8 0.1 0.1" contype="1" margin="0.001" material="geom" rgba="0.8 0.6 .4 0.8"/>
		<motor ctrllimited="true" ctrlrange="-.4 .4"/>
	</default>

	<option integrator="RK4" iterations="50" solver="PGS" timestep="0.003">
		<!-- <flags solverstat="enable" energy="enable"/>-->
	</option>
	<size nkey="5" nuser_geom="1"/>
	<visual>
		<map fogend="5" fogstart="3"/>
	</visual>
	<worldbody>
		<!-- Pelvis -->
		<geom fromto="-.02 -.07 0 -.02 .07 0" name="butt" size="0.09" type="capsule"/>
		
		<!-- lower waist -->
		<body name="lwaist" pos="-.01 0 0.10" quat="1.000 0 -0.002 0">
			<!-- Three different joints connected to the butat. less independent movement in
			the upper torso. -->
			<joint armature="0.02" axis="1 0 0" damping="5" name="abdomen_x" pos="0 0 -0.1" range="-35 35" stiffness="10" type="hinge"/>
			<joint armature="0.02" axis="0 1 0" damping="5" name="abdomen_y" pos="0 0 -0.065" range="-75 30" stiffness="10" type="hinge"/>
			<joint armature="0.02" axis="0 0 1" damping="5" name="abdomen_z" pos="0 0 -0.065" range="-45 45" stiffness="20" type="hinge"/>
			<geom fromto="0 -.06 0 0 .06 0" name="lwaist" size="0.06" type="capsule"/>

			<!-- upper waist -->
			<body name="uwaist" pos="-.01 0 0.160" quat="1.000 0 -0.002 0">
				<joint armature="0.02" axis="0 0 1" damping="5" name="upper_abs" pos="0 0 0.015" range="-10 10" stiffness="20" type="hinge"/>
				<geom fromto="0 -.07 0 0 .07 0" name="torso1" size="0.07" type="capsule"/>
				<!-- <geom fromto="&#45;.01 &#45;.06 &#45;.12 &#45;.01 .06 &#45;.12" name="uwaist" size="0.06" type="capsule"/> -->
				<!-- head -->
				<body name="head" pos="-.01 0 0.04" quat="1.000 0 -0.002 0">
		<joint armature="0.02" axis="1 0 0" damping="3" name="neck_x" pos="0 0 0.01" range="-15 15" stiffness="3" type="hinge"/>
					<joint armature="0.02" axis="0 1 0" damping="3" name="neck_y" pos="0 0 0.01" range="-15 15" stiffness="3" type="hinge"/>
					<joint armature="0.02" axis="0 0 1" damping="3" name="neck_z" pos="0 0 0.01" range="-15 15" stiffness="3" type="hinge"/>
					<geom name="head" pos="0 0 .17" size=".09" type="sphere" user="258"/>
				</body>

				<!-- Shoulder -->
				<body name="right_shoulder" pos="0 -0.17 0.06">
					<geom contype="0" name="right_shoulder" pos="0 0 0" rgba="1.0 0.0 0.0 1" size=".03" type="sphere"/>
				</body>

				<!-- R-arm -->
				<body name="right_upper_arm" pos="0 -0.17 0.06">
					<geom contype="0" name="right_shoulder" pos="0 0 0" rgba="1.0 0.0 0.0 1" size=".03" type="sphere"/>
					<joint armature="0.0068" axis="2 1 1" name="right_shoulder1" pos="0 0 0" range="-85 60" stiffness="1" type="hinge"/>
					<joint armature="0.0051" axis="0 -1 1" name="right_shoulder2" pos="0 0 0" range="-85 60" stiffness="1" type="hinge"/>
					<geom fromto="0 0 0 .16 -.16 -.16" name="right_uarm1" size="0.04 0.16" type="capsule"/>

					<!-- Elbow -->
					<body name="right_elbow" pos=".18 -.18 -.18">
						<geom contype="0" name="right_elbow" pos="0 0 0" rgba="1.0 0.0 0.0 1" size=".03" type="sphere"/>
					</body>

					<body name="right_lower_arm" pos=".18 -.18 -.18">
						<joint armature="0.0028" axis="0 -1 1" name="right_elbow" pos="0 0 0" range="-90 50" stiffness="0" type="hinge"/>
						<geom fromto="0.01 0.01 0.01 .17 .17 .17" name="right_larm" size="0.031" type="capsule"/>

						<!-- Hand -->
						<body name="right_hand" pos=".18 .18 .18">
							<geom contype="0" name="right_hand" pos="0 0 0" rgba="1.0 0.0 0.0 1" size=".03" type="sphere"/>
						</body>

					</body>
				</body>

				<!-- Shoulder -->
				<body name="left_shoulder" pos="0 0.17 0.06">
					<geom contype="0" name="left_shoulder" pos="0 0 0" rgba="1.0 0.0 0.0 1" size=".03" type="sphere"/>
				</body>

				<!-- L-arm -->
				<body name="left_upper_arm" pos="0 0.17 0.06">
					<joint armature="0.0068" axis="2 -1 1" name="left_shoulder1" pos="0 0 0" range="-60 85" stiffness="1" type="hinge"/>
					<joint armature="0.0051" axis="0 1 1" name="left_shoulder2" pos="0 0 0" range="-60 85" stiffness="1" type="hinge"/>
					<geom fromto="0 0 0 .16 .16 -.16" name="left_uarm1" size="0.04 0.16" type="capsule"/>

					<!-- Elbow -->
					<body name="left_elbow" pos=".18 .18 -.18">
						<geom contype="0" name="left_elbow" pos="0 0 0" rgba="1.0 0.0 0.0 1" size=".03" type="sphere"/>
					</body>

					<body name="left_lower_arm" pos=".18 .18 -.18">
						<joint armature="0.0028" axis="0 -1 -1" name="left_elbow" pos="0 0 0" range="-90 50" stiffness="0" type="hinge"/>
						<geom fromto="0.01 -0.01 0.01 .17 -.17 .17" name="left_larm" size="0.031" type="capsule"/>

						<!-- Hand -->
						<body name="left_hand" pos=".18 -.18 .18">
							<geom contype="0" name="left_hand" pos="0 0 0" rgba="0.9 0.0 0.9 1" size=".03" type="sphere"/>
						</body>

					</body>
				</body>
			</body>
		</body>

		<!-- Target -->
		<body name="target0" pos="0 0 .01">
			<joint armature="0" axis="1 0 0" damping="0" limited="true" name="target0_x" pos="0 0 0" range="-.27 .27" stiffness="0" type="slide"/>
			<joint armature="0" axis="0 1 0" damping="0" limited="true" name="target0_y" pos="0 0 0" range="-.27 .27" stiffness="0" type="slide"/>
			<joint armature="0" axis="0 0 1" damping="0" limited="true" name="target0_z" pos="0 0 0" range="-.27 .27" stiffness="0" type="slide"/>
			<geom conaffinity="0" contype="0" name="target0" pos="0 0 0" rgba="0.9 0.2 0.9 1" size=".05" type="sphere"/>
		</body>
    <!--  -->
		<!-- <!&#45;&#45; Target &#45;&#45;> -->
		<!-- <body name="target1" pos="0 0 .01"> -->
		<!-- 	<joint armature="0" axis="1 0 0" damping="0" limited="true" name="target1_x" pos="0 0 0" range="&#45;.27 .27" stiffness="0" type="slide"/> -->
		<!-- 	<joint armature="0" axis="0 1 0" damping="0" limited="true" name="target1_y" pos="0 0 0" range="&#45;.27 .27" stiffness="0" type="slide"/> -->
		<!-- 	<joint armature="0" axis="0 0 1" damping="0" limited="true" name="target1_z" pos="0 0 0" range="&#45;.27 .27" stiffness="0" type="slide"/> -->
		<!-- 	<geom conaffinity="0" contype="0" name="target1" pos="0 0 0" rgba="0.1 0.2 0.9 1" size=".05" type="sphere"/> -->
		<!-- </body> -->
    <!--  -->
		<!-- <!&#45;&#45; Target &#45;&#45;> -->
		<!-- <body name="target2" pos="0 0 .01"> -->
		<!-- 	<joint armature="0" axis="1 0 0" damping="0" limited="true" name="target2_x" pos="0 0 0" range="&#45;.27 .27" stiffness="0" type="slide"/> -->
		<!-- 	<joint armature="0" axis="0 1 0" damping="0" limited="true" name="target2_y" pos="0 0 0" range="&#45;.27 .27" stiffness="0" type="slide"/> -->
		<!-- 	<joint armature="0" axis="0 0 1" damping="0" limited="true" name="target2_z" pos="0 0 0" range="&#45;.27 .27" stiffness="0" type="slide"/> -->
		<!-- 	<geom conaffinity="0" contype="0" name="target2" pos="0 0 0" rgba="0.2 0.9 0.2 1" size=".05" type="sphere"/> -->
		<!-- </body> -->

	</worldbody>
	<actuator><!-- this section is not supported, same constants in code -->
		<motor gear="100" joint="abdomen_y" name="abdomen_y"/>
		<motor gear="100" joint="abdomen_z" name="abdomen_z"/>
		<motor gear="100" joint="abdomen_x" name="abdomen_x"/>
		<motor gear="100" joint="upper_abs" name="upper_abs"/>
		<motor gear="25" joint="neck_y" name="neck_y"/>
		<motor gear="25" joint="neck_z" name="neck_z"/>
		<motor gear="25" joint="neck_x" name="neck_x"/>
		<motor gear="25" joint="right_shoulder1" name="right_shoulder1"/>
		<motor gear="25" joint="right_shoulder2" name="right_shoulder2"/>
		<motor gear="25" joint="right_elbow" name="right_elbow"/>
		<motor gear="25" joint="left_shoulder1" name="left_shoulder1"/>
		<motor gear="25" joint="left_shoulder2" name="left_shoulder2"/>
		<motor gear="25" joint="left_elbow" name="left_elbow"/>
	</actuator>
</mujoco>
